# 异常

- 产生

  - throw 异常对象  抛出一个异常

  - 传递 ： 沿着方法调用，反向传递

    

- 异常的处理

  - 声明抛出 throws

    - ```
       private static void mc(int i) throws EOFException, FileNotFoundException {
              System.out.println("mc1");
              if (i == 0){
                  throw new NullPointerException();
              }
              if  (i == 1){
                  throw new EOFException();
              }
              if (i == 2){
                  throw new FileNotFoundException();
              }
              System.out.println("mc2");
              System.out.println("mc3");
        
          }
      ```

      

    - ```
      package TestException;
      
      import java.io.EOFException;
      import java.io.FileNotFoundException;
      import java.io.IOException;
      
      public class testexception {
          public static void main(String[] args) throws Throwable{
              System.out.println("main 1");
              ma(1);
              System.out.println("main 2");
          }
      
          private static void ma(int i) throws Exception {
              System.out.println("ma1");
              mb(i);
              System.out.println("ma2");
              System.out.println("ma3");
          }
      
          private static void mb(int i) throws IOException {
              System.out.println("mb1");
              mc(i);
              System.out.println("mb2");
              System.out.println("mb3");
          }
      
          private static void mc(int i) throws EOFException, FileNotFoundException {
              System.out.println("mc1");
              if (i == 0){
                  throw new NullPointerException();
              }
              if  (i == 1){
                  throw new EOFException();
              }
              if (i == 2){
                  throw new FileNotFoundException();
              }
              System.out.println("mc2");
              System.out.println("mc3");
      
          }
      }
      
      ```

      

  - 捕获异常 try- catch  多个catch 先catch子类异常，再catch父类异常

    - ```
      private static void ma(int i)  {
            System.out.println("ma1");
            try {
                mb(i);
            } catch (IOException e) {
                System.out.println("catch ioexception");
            }
            System.out.println("ma2");
            System.out.println("ma3");
        }
        
      ```

      - printStackTrace（）：打印异常栈追踪信息

      - try-catch-finally    finally无论如何都会执行，通常用来释放资源

      - try-finally  利用finally一定会执行

      - ```
        package Testfinally;
        
        public class testfinally {
            public static void main(String[] args){
                System.out.println(fun());
        
                }
            static int fun(){
                int a = 10;
                try{
                    a = 20;
                    return a;
                }finally {
                    a = 30;
                }
        
            }
        }
        
        // 20
        ```

        

​             

- 方法覆盖
  - 子类方法不能抛出一个父类方法没有抛出的异常
  - 子类方法抛出异常必须是父类方法抛出异常的  同类，子类，不抛